Workbook

Sheet Main
B2: $AYI | G2: Lighting & control products
B3: Acuity Brands Inc.
B5: Stock Snapshot | O5: Product Lines
B6: Price | C6: 360.38 | O6: Acuity Brands | R6: lighting products
B7: Shares | C7: =+'Financial Model'!N24 -> 30.705 | D7: FQ126 | O7: Acuity Intelligent Spaces | R7: "smart buildings"
B8: MC | C8: =C6*C7 -> 11065.468
B9: Cash | C9: =+'Financial Model'!N68 -> 376.1 | D9: FQ126
B10: Debt | C10: =+'Financial Model'!N69 -> 797 | D10: FQ126
B11: Net Cash | C11: =+C9-C10 -> -420.9 | D11: FQ126
B12: EV | C12: =+C8-C11 -> 11486.368
B15: Management
A16: 43831 | B16: CEO | C16: Neil Ashe
B17: CFO
B18: COO
B22: Profile
B23: HQ | C23: Atlanta, GA
B24: Founded | C24: 2001
B25: IPO
B27: Inventory
B29: Update | C29: FQ425 | D29: 37165
B30: IR | C30: Link
B33: Valuation Metrics
B34: P/B | C34: =+C6/'Financial Model'!N66 -> 3.9604395
B35: P/S | C35: =+C8/SUM('Financial Model'!K12:N12) -> 2.4385631
B37: P/E | C37: =+C6/SUM('Financial Model'!K23:N23) -> 27.037829

Sheet Financial Model
F1: FQ124 | G1: FQ224 | H1: FQ324 | I1: FQ424 | J1: FQ125 | K1: FQ225 | L1: FQ325 | M1: FQ425 | N1: FQ126 | O1: FQ226 | Q1: FY18 | R1: FY19 | S1: FY20 | T1: FY21 | U1: FY22 | V1: FY23 | W1: FY24 | X1: FY25 | Y1: FY26 | Z1: FY27 | AA1: FY28 | AB1: FY29 | AC1: FY30 | AD1: FY31
F2: 45260 | G2: 45351 | H2: 45443 | I2: 45535 | J2: 45991 | K2: 45716 | L2: 45808 | M2: 45900 | N2: 46356
J3: 45665 | K3: 45750 | L3: 45834 | M3: 45931 | N3: 46030
B4: Independent Sales | F4: 625.2 | G4: 612.3 | H4: 637.1 | I4: 677.1 | J4: 643.9 | K4: 615.2 | L4: 685.3 | M4: 702.4 | N4: 666.3
B5: Direct Sales | F5: 97.4 | G5: 93 | H5: 97 | I5: 109.6 | J5: 107.2 | K5: 97.4 | L5: 101.5 | M5: 105.3 | N5: 90.4
B6: Retail Sales | F6: 55.6 | G6: 46.4 | H6: 45.7 | I6: 42.6 | J6: 44.9 | K6: 41 | L6: 41.4 | M6: 43.4 | N6: 46.8
B7: Corporate Accounts | F7: 41.5 | G7: 38.1 | H7: 60.5 | I7: 65.8 | J7: 32.7 | K7: 35.6 | L7: 35.5 | M7: 52.9 | N7: 39.9
B8: OEM & Other | F8: 56.7 | G8: 53.7 | H8: 58.2 | I8: 59.9 | J8: 57.3 | K8: 51.4 | L8: 59.5 | M8: 58.4 | N8: 51.7
B9: Total Acuity Brands | F9: =+SUM(F4:F8) -> 876.4 | G9: =+SUM(G4:G8) -> 843.5 | H9: =+SUM(H4:H8) -> 898.5 | I9: =+SUM(I4:I8) -> 955 | J9: =+SUM(J4:J8) -> 886 | K9: =+SUM(K4:K8) -> 840.6 | L9: =+SUM(L4:L8) -> 923.2 | M9: =+SUM(M4:M8) -> 962.4 | N9: =+SUM(N4:N8) -> 895.1
B10: Acuity Intelligent Spaces | F10: 64.2 | G10: 68.1 | H10: 75.7 | I10: 83.9 | J10: 73.5 | K10: 171.5 | L10: 264.1 | M10: 255.2 | N10: 257.4
B11: Eliminations | F11: -5.9 | G11: -5.7 | H11: -6.1 | I11: -6.6 | J11: -7.9 | K11: -5.8 | L11: -8.7 | M11: -8.5 | N11: -8.8
B12: Revenue | F12: 934.7 | G12: 905.9 | H12: 968.1 | I12: 1032.3 | J12: 951.6 | K12: 1006.3 | L12: 1178.6 | M12: 1209.1 | N12: 1143.7 | W12: =+SUM(F12:I12) -> 3841 | X12: =+SUM(J12:M12) -> 4345.6
B13: COGS | F13: 506.3 | G13: 493.5 | H13: 515.9 | I13: 543.6 | J13: 502.3 | K13: 538.3 | L13: 608.4 | M13: 618.1 | N13: 589.9 | X13: =+SUM(J13:M13) -> 2267.1
B14: Gross Profit | F14: =+F12-F13 -> 428.4 | G14: =+G12-G13 -> 412.4 | H14: =+H12-H13 -> 452.2 | I14: =+I12-I13 -> 488.7 | J14: =+J12-J13 -> 449.3 | K14: =+K12-K13 -> 468 | L14: =+L12-L13 -> 570.2 | M14: =+M12-M13 -> 591 | N14: =+N12-N13 -> 553.8 | X14: =+X12-X13 -> 2078.5
B15: SD&A | F15: 295.5 | G15: 294.3 | H15: 306.9 | I15: 331.7 | J15: 316 | K15: 357.8 | L15: 400.7 | M15: 410.4 | N15: 393.4 | X15: =+SUM(J15:M15) -> 1484.9
B16: Special Charges | F16: 0 | G16: 0 | H16: 0 | I16: 0 | J16: 0 | K16: 0 | L16: 29.7 | M16: 0 | N16: 0 | X16: =+SUM(J16:M16) -> 29.7
B17: Operating Income | F17: =+F14-F15-F16 -> 132.9 | G17: =+G14-G15-G16 -> 118.1 | H17: =+H14-H15-H16 -> 145.3 | I17: =+I14-I15-I16 -> 157 | J17: =+J14-J15-J16 -> 133.3 | K17: =+K14-K15-K16 -> 110.2 | L17: =+L14-L15-L16 -> 139.8 | M17: =+M14-M15-M16 -> 180.6 | N17: =+N14-N15-N16 -> 160.4 | X17: =+X14-X15-X16 -> 563.9
B18: Interest Expense | F18: 0.9 | G18: -0.1 | H18: -1.8 | I18: -3.5 | J18: -4 | K18: 6.9 | L18: 12.1 | M18: 7 | N18: 8.4 | X18: =+SUM(J18:M18) -> 22
B19: Misc Expense | F19: 1.1 | G19: 0.6 | H19: -0.5 | I19: 8 | J19: 2.5 | K19: 1 | L19: 2.3 | M19: 35.9 | N19: -0.6 | X19: =+SUM(J19:M19) -> 41.7
B20: Pretax Income | F20: =+F17-F18-F19 -> 130.9 | G20: =+G17-G18-G19 -> 117.6 | H20: =+H17-H18-H19 -> 147.6 | I20: =+I17-I18-I19 -> 152.5 | J20: =+J17-J18-J19 -> 134.8 | K20: =+K17-K18-K19 -> 102.3 | L20: =+L17-L18-L19 -> 125.4 | M20: =+M17-M18-M19 -> 137.7 | N20: =+N17-N18-N19 -> 152.6 | X20: =+X17-X18-X19 -> 500.2
B21: Taxes | F21: 30.3 | G21: 28.4 | H21: 33.7 | I21: 33.6 | J21: 28.1 | K21: 24.8 | L21: 27 | M21: 23.7 | N21: 32.1 | X21: =+SUM(J21:M21) -> 103.6
B22: Net Income | F22: =+F20-F21 -> 100.6 | G22: =+G20-G21 -> 89.2 | H22: =+H20-H21 -> 113.9 | I22: =+I20-I21 -> 118.9 | J22: =+J20-J21 -> 106.7 | K22: =+K20-K21 -> 77.5 | L22: =+L20-L21 -> 98.4 | M22: =+M20-M21 -> 114 | N22: =+N20-N21 -> 120.5 | X22: =+X20-X21 -> 396.6
B23: EPS | F23: =+F22/F24 -> 3.244638 | G23: =+G22/G24 -> 2.8900985 | H23: =+H22/H24 -> 3.6945733 | I23: =+I22/I24 -> 3.8587609 | J23: =+J22/J24 -> 3.4497252 | K23: =+K22/K24 -> 2.5000806 | L23: =+L22/L24 -> 3.1895238 | M23: =+M22/M24 -> 3.714686 | N23: =+N22/N24 -> 3.9244423 | X23: =+X22/X24 -> 12.923197
B24: Shares | F24: 31.005 | G24: 30.864 | H24: 30.829 | I24: 30.813 | J24: 30.93 | K24: 30.999 | L24: 30.851 | M24: 30.689 | N24: 30.705 | X24: =+M24 -> 30.689
B26: Gross Margin | F26: =+F14/F12 -> 0.45832888 | G26: =+G14/G12 -> 0.45523788 | H26: =+H14/H12 -> 0.46710051 | I26: =+I14/I12 -> 0.47340889 | J26: =+J14/J12 -> 0.47215216 | K26: =+K14/K12 -> 0.46507006 | L26: =+L14/L12 -> 0.48379433 | M26: =+M14/M12 -> 0.48879332 | N26: =+N14/N12 -> 0.48421789 | X26: =+X14/X12 -> 0.47829989
B27: Operating Margin | F27: =+F17/F12 -> 0.14218466 | G27: =+G17/G12 -> 0.13036759 | H27: =+H17/H12 -> 0.1500878 | I27: =+I17/I12 -> 0.15208757 | J27: =+J17/J12 -> 0.14007987 | K27: =+K17/K12 -> 0.10951009 | L27: =+L17/L12 -> 0.11861531 | M27: =+M17/M12 -> 0.1493673 | N27: =+N17/N12 -> 0.14024657 | X27: =+X17/X12 -> 0.12976344
B28: Net Margin | F28: =+F22/F12 -> 0.10762812 | G28: =+G22/G12 -> 0.098465614 | H28: =+H22/H12 -> 0.11765314 | I28: =+I22/I12 -> 0.1151797 | J28: =+J22/J12 -> 0.11212694 | K28: =+K22/K12 -> 0.077014807 | L28: =+L22/L12 -> 0.083488885 | M28: =+M22/M12 -> 0.094285005 | N28: =+N22/N12 -> 0.1053598 | X28: =+X22/X12 -> 0.091264728
B29: Tax Rate | F29: =+F21/F20 -> 0.23147441 | G29: =+G21/G20 -> 0.2414966 | H29: =+H21/H20 -> 0.22831978 | I29: =+I21/I20 -> 0.22032787 | J29: =+J21/J20 -> 0.20845697 | K29: =+K21/K20 -> 0.24242424 | L29: =+L21/L20 -> 0.215311 | M29: =+M21/M20 -> 0.17211329 | N29: =+N21/N20 -> 0.21035387 | X29: =+X21/X20 -> 0.20711715
B31: Revenue Y/Y | J31: =+J12/F12-1 -> 0.018080668 | K31: =+K12/G12-1 -> 0.11082901 | L31: =+L12/H12-1 -> 0.21743622 | M31: =+M12/I12-1 -> 0.17126804 | N31: =+N12/J12-1 -> 0.20187053 | X31: =+X12/W12-1 -> 0.13137204
B32: Acuity Brands Y/Y | J32: =+J9/F9-1 -> 0.010953902 | K32: =+K9/G9-1 -> -0.0034380557 | L32: =+L9/H9-1 -> 0.027490262 | M32: =+M9/I9-1 -> 0.0077486911 | N32: =+N9/J9-1 -> 0.01027088
B33: Acuity Intelligent Y/Y | J33: =+J10/F10-1 -> 0.14485981 | K33: =+K10/G10-1 -> 1.5183554 | L33: =+L10/H10-1 -> 2.4887715 | M33: =+M10/I10-1 -> 2.0417163 | N33: =+N10/J10-1 -> 2.5020408
B34: Revenue Q/Q | G34: =+G12/F12-1 -> -0.030812025 | H34: =+H12/G12-1 -> 0.068661 | I34: =+I12/H12-1 -> 0.066315463 | J34: =+J12/I12-1 -> -0.078174949 | K34: =+K12/J12-1 -> 0.057482135 | L34: =+L12/K12-1 -> 0.17122131 | M34: =+M12/L12-1 -> 0.025878161 | N34: =+N12/M12-1 -> -0.054089819
B37: Balance Sheet
B38: Cash | M38: 422.5 | N38: 376.1
B39: AR | M39: 593.9 | N39: 565.3
B40: Inventories | M40: 526.7 | N40: 518.1
B41: Prepayments & OCA | M41: 108.4 | N41: 122
B42: TCA | M42: =+SUM(M38:M41) -> 1651.5 | N42: =+SUM(N38:N41) -> 1581.5
B43: PP&E | M43: 343.2 | N43: 345
B44: Operating Lease ROU | M44: 0 | N44: 103.6
...
