Workbook

Sheet Main
B2: £BOWL | H2: The UK & Canada's largest ten-pin bowling operator
B3: Hollywood Bowl Group Plc
B5: Stock Snapshot | H5: Competitors | O5: Key Events
B6: Price | C6: 3.04 | H6: Company | L6: No Sites
B7: Shares | C7: =+'Financial Model'!T14 -> 167.07665 | D7: FY25 | H7: Ten Entertainment Group | L7: =[1]Main!$C$25 -> 51 | O7: 45689 | P7: BOWL announce buyback programme up to 17mil shares
B8: MC | C8: =C6*C7 -> 507.91302 | H8: QLP | L8: 11
B9: Cash | C9: =+'Financial Model'!T70 -> 25.994 | D9: FY25 | H9: Disco Bowl | L9: 6 | O9: 45627 | P9: Puttstars written down as impairment due to poor performance FY24
B10: Debt | C10: =+'Financial Model'!T71 -> 0 | D10: FY25 | H10: Namco | L10: 7
B11: Net Cash | C11: =C9-C10 -> 25.994 | D11: FY25 | H11: MFA | L11: 6 | O11: 45200 | P11: Hollywood Bowl acquire Lincoln Bowl in the UK
B12: EV | C12: =C8-C11 -> 481.91902 | H12: Others | L12: 174
O13: 44866 | P13: £BOWL strikes deal for 36k SQFT site in Birmingham, Merry Hill
B15: Management
B16: CEO | C16: Steve Burns
B17: CFO | C17: Laurence Keen | H17: Highlighted Risks
H18: Adverse Economic Conditions
H19: Decline in discretionary leisure activity could impact sales
P20: Scrape reviews
H21: IT Outages/Glitches/Issues | P21: https://www.trustpilot.com/review/www.hollywoodbowl.co.uk
B22: Profile | H22: Customers may not be able to book through website
B23: HQ | C23: Hemel, UK | H23: Also reliant on Microsoft Azure & 365 for cloud/email
B24: Founded | C24: 2010
B25: Sites | C25: =+'Financial Model'!AD25 -> 85 | O25: 38% of UK estate fitted with Solar Panels to subsidise energy usage
B26: Emply. | C26: =+'Financial Model'!AE34 -> 2882
B27: IPO | C27: 2016
B28: Update | C28: FY25 | D28: 46027
B29: IR | C29: Link | H29: Mitigations to Highlighted Risks
H30: Adverse Economic Conditions
H31: Lowest price-per-game of any branded operators
B32: Ratios | H32: Majority of centre-locations based in high footfall areas
B33: P/B | C33: =+C6/'Financial Model'!T68 -> 3.2371148
B34: P/S | C34: =+C8/SUM('Financial Model'!S3:T3) -> 1.9315807 | H34: IT Outages/Glitches/Issues
B35: EV/S | C35: =+C12/SUM('Financial Model'!S3:T3) -> 1.8327262 | H35: All core systems are backed up (disaster recovery centre)
B36: P/E | C36: =+C6/SUM('Financial Model'!S13:T13) -> 15.284303
B37: EV/E | C37: =+C12/SUM('Financial Model'!S12:T12) -> 14.376201
B38: P/FCF | C38: =+C6/'Financial Model'!T89 -> 0.15979815
B39: Stockopedia | C39: 61

Sheet Financial Model
D1: H118 | E1: H218 | F1: H119 | G1: H219 | H1: H120 | I1: H220 | J1: H121 | K1: H221 | L1: H122 | M1: H222 | N1: H123 | O1: H223 | P1: H124 | Q1: H224 | R1: H125 | S1: H225 | T1: H126 | V1: FY16 | W1: FY17 | X1: FY18 | Y1: FY19 | Z1: FY20 | AA1: FY21 | AB1: FY22 | AC1: FY23 | AD1: FY24 | AE1: FY25 | AF1: FY24 | AG1: FY25 | AH1: FY26 | AI1: FY27 | AJ1: FY28 | AK1: FY29 | AL1: FY30 | AM1: FY31 | AN1: FY32 | AO1: FY33 | AP1: FY34 | AQ1: FY35 | AR1: FY36 | AS1: FY37 | AT1: FY38 | AU1: FY39
F2: 43921 | G2: 43738 | H2: 43921 | I2: 44104 | J2: 44286 | K2: 44469 | L2: 44651 | M2: 44834 | N2: 45016 | O2: =AC2 -> 45199 | P2: 45382 | Q2: =+AD2 -> 45565 | R2: 45747 | S2: =+AE2 -> 45930 | T2: 46112 | V2: 42643 | W2: 43008 | X2: 43373 | Y2: 43738 | Z2: 44104 | AA2: 44469 | AB2: 44834 | AC2: 45199 | AD2: 45565 | AE2: 45930 | AF2: (Projected) | AG2: (Projected) | AH2: (Projected) | AI2: (Projected) | AJ2: (Projected) | AK2: (Projected) | AL2: (Projected) | AM2: (Projected) | AN2: (Projected) | AO2: (Projected) | AP2: (Projected) | AQ2: (Projected) | AR2: (Projected) | AS2: (Projected) | AT2: (Projected) | AU2: (Projected)
B3: Revenue | F3: 66.99 | G3: =Y3-F3 -> 62.904 | H3: 69.23 | I3: =Z3-H3 -> 10.243 | J3: 10.433 | K3: =AA3-J3 -> 61.445 | L3: 100.173 | M3: =AB3-L3 -> 93.568 | N3: 110.052 | O3: =AC3-N3 -> 105.03 | P3: 119.187 | Q3: =+AD3-P3 -> 111.212 | R3: 129.249 | S3: =+AE3-R3 -> 121.413 | T3: 141.539 | V3: 104.803 | W3: 113.968 | X3: 120.548 | Y3: 129.894 | Z3: 79.473 | AA3: 71.878 | AB3: 193.741 | AC3: 215.082 | AD3: 230.399 | AE3: 250.662 | AF3: =AC3*(1+AF21) -> 238.74102 | AG3: =AF3*(1+AG21) -> 257.8403 | AH3: =AG3*(1+AH21) -> 275.88912 | AI3: =AH3*(1+AI21) -> 292.44247 | AJ3: =AI3*(1+AJ21) -> 307.06459 | AK3: =AJ3*(1+AK21) -> 322.41782 | AL3: =AK3*(1+AL21) -> 338.53871 | AM3: =AL3*(1+AM21) -> 352.08026 | AN3: =AM3*(1+AN21) -> 366.16347 | ... AU3: =AT3*(1+AU21) -> 428.85392
B4: COGS | F4: 9.474 | G4: =Y4-F4 -> 9.068 | H4: 9.976 | I4: =Z4-H4 -> 1.567 | J4: 1.192 | K4: =AA4-J4 -> 9.065 | L4: 13.641 | M4: =AB4-L4 -> 15.751 | N4: 18.972 | O4: =AC4-N4 -> 59.236 | P4: =19.825+22.269 -> 42.094 | Q4: =+AD4-P4 -> 42.807 | R4: =21.95+24.869 -> 46.819 | S4: =+AE4-R4 -> 46.875 | T4: =23.24+29.461 -> 52.701 | V4: 15.376 | W4: 15.349 | X4: 16.748 | Y4: 18.542 | Z4: 11.543 | AA4: 10.257 | AB4: 29.392 | AC4: =37.491+40.717 -> 78.208 | AD4: =39.178+45.723 -> 84.901 | AE4: =41.851+51.843 -> 93.694 | AF4: =AF3*0.16 -> 38.198563 | AG4: =AG3*0.38 -> 97.979315 | AH4: =AH3*0.38 -> 104.83787 | AI4: =AI3*0.38 -> 111.12814 | AJ4: =AJ3*0.38 -> 116.68455 | AK4: =AK3*0.38 -> 122.51877 | AL4: =AL3*0.38 -> 128.64471 | AM4: =AM3*0.38 -> 133.7905 | AN4: =AN3*0.38 -> 139.14212 | ... AU4: =AU3*0.38 -> 162.96449
B5: Gross Profit | F5: =F3-F4 -> 57.516 | G5: =Y5-F5 -> 53.836 | H5: =H3-H4 -> 59.254 | I5: =I3-I4 -> 8.676 | J5: =J3-J4 -> 9.241 | K5: =K3-K4 -> 52.38 | L5: =L3-L4 -> 86.532 | M5: =M3-M4 -> 77.817 | N5: =N3-N4 -> 91.08 | O5: =O3-O4 -> 45.794 | ... T5: =T3-T4 -> 88.838 | V5: =V3-V4 -> 89.427 | W5: =W3-W4 -> 98.619 | X5: =X3-X4 -> 103.8 | Y5: =Y3-Y4 -> 111.352 | Z5: =Z3-Z4 -> 67.93 | AA5: =AA3-AA4 -> 61.621 | AB5: =AB3-AB4 -> 164.349 | AC5: =AC3-AC4 -> 136.874 | ... AU5: =AU3-AU4 -> 265.88943
B6: Other Income | F6: 0 | G6: =Y6-F6 -> 0 | H6: 0 | I6: =Z6-H6 -> 0 | J6: 1.594 | K6: =AA6-J6 -> 1.22 | L6: 0 | M6: =AB6-L6 -> 0.039 | N6: 0 | O6: =AC6-N6 -> 0 | P6: 0 | Q6: =+AD6-P6 -> 0.607 | R6: 1.613 | S6: =+AE6-R6 -> 0 | T6: 0 | V6: 1.395 | W6: 0.08 | X6: 0 | Y6: 0 | Z6: 0 | AA6: 2.814 | AB6: 0.039 | AC6: 0 | AD6: 0.607 | AE6: 1.613 | AF6: =-AVERAGE(Y6:AC6) -> -0.5706 | AG6: =AVERAGE(V6:AF6) -> 0.5434 | AH6: =AVERAGE(W6:AG6) -> 0.46598182 | AI6: =AVERAGE(X6:AH6) -> 0.50107107 | AJ6: =AVERAGE(Y6:AI6) -> 0.54662299 | AK6: =AVERAGE(Z6:AJ6) -> 0.59631599 | AL6: =AVERAGE(AA6:AK6) -> 0.65052653 | AM6: =AVERAGE(AB6:AL6) -> 0.45384713 | AN6: =AVERAGE(AF6:AM6) -> 0.39839569 | AO6: =AVERAGE(AG6:AN6) -> 0.51952015 | AP6: =AVERAGE(AH6:AO6) -> 0.51653517 | AQ6: =AVERAGE(AI6:AP6) -> 0.52285434 | AR6: =AVERAGE(AJ6:AQ6) -> 0.52557725 | AS6: =AVERAGE(AK6:AR6) -> 0.52294653 | AT6: =AVERAGE(AL6:AS6) -> 0.51377535 | AU6: =AVERAGE(AM6:AT6) -> 0.49668145
B7: Administrative Expenses | F7: 40.753 | G7: =Y7-F7 -> 42.155 | H7: 40.078 | I7: =Z7-H7 -> 17.991 | J7: 20.857 | K7: =AA7-J7 -> 33.998 | L7: 48.916 | M7: =AB7-L7 -> 60.023 | N7: 58.934 | O7: =AC7-N7 -> 23.855 | P7: 42.725 | Q7: =+AD7-P7 -> 49.874 | R7: 49.155 | S7: =+AE7-R7 -> 51.202 | T7: 54.138 | V7: 76.444 | W7: 76.498 | X7: 78.908 | Y7: 82.908 | Z7: 58.069 | AA7: 54.855 | AB7: 108.939 | AC7: 82.789 | AD7: 92.599 | AE7: 100.357 | AF7: =AF5*0.62 -> 124.33632 | AG7: =AG5*0.63 -> 100.71242 | AH7: =AH5*0.63 -> 107.76229 | AI7: =AI5*0.63 -> 114.22803 | AJ7: =AJ5*0.63 -> 119.93943 | AK7: =AK5*0.63 -> 125.9364 | AL7: =AL5*0.63 -> 132.23322 | AM7: =AM5*0.63 -> 137.52255 | AN7: =AN5*0.63 -> 143.02345 | ... AU7: =AU5*0.63 -> 167.51034
B8: Operating Income | F8: =F5+F6-F7 -> 16.763 | G8: =Y8-F8 -> 11.681 | H8: =H5+H6-H7 -> 19.176 | I8: =I5+I6-I7 -> -9.315 | J8: =J5+J6-J7 -> -10.022 | K8: =K5+K6-K7 -> 19.602 | L8: =L5+L6-L7 -> 37.616 | M8: =M5+M6-M7 -> 17.833 | N8: =N5+N6-N7 -> 32.146 | O8: =O5+O6-O7 -> 21.939 | ... T8: =T5+T6-T7 -> 34.7 | V8: =V5+V6-V7 -> 14.378 | W8: =W5+W6-W7 -> 22.201 | X8: =X5+X6-X7 -> 24.892 | Y8: =Y5+Y6-Y7 -> 28.444 | Z8: =Z5+Z6-Z7 -> 9.861 | AA8: =AA5+AA6-AA7 -> 9.58 | AB8: =AB5+AB6-AB7 -> 55.449 | AC8: =AC5+AC6-AC7 -> 54.085 | ... AU8: =AU5+AU6-AU7 -> 98.875772
B9: Finance Expenses | F9: =0.482-0.104 -> 0.378 | G9: =Y9-F9 -> 0.478 | H9: =4.773-0.065 -> 4.708 | I9: =Z9-H9 -> 3.957 | J9: 4.467 | K9: =AA9-J9 -> 4.651 | L9: 4.179 | M9: =AB9-L9 -> 4.605 | N9: 4.457 | O9: =AC9-N9 -> 4.548 | P9: =-1.029+5.869 -> 4.84 | Q9: =+AD9-P9 -> 5.908 | R9: =-0.555+7.109 -> 6.554 | S9: =+AE9-R9 -> 7.386 | T9: =-0.329+7.797 -> 7.468 | V9: =-0.022+11.905-0.079 -> 11.804 | W9: =1.158-0.012+0.055 -> 1.201 | X9: =0.976-0.018 -> 0.958 | Y9: =1.023-0.167 -> 0.856 | Z9: =8.743-0.078 -> 8.665 | AA9: 9.118 | AB9: =-0.012+8.796 -> 8.784 | AC9: =10.445-1.44 -> 9.005 | AD9: =-1.722+12.47 -> 10.748 | AE9: =-0.827+14.767 -> 13.94 | AF9: =AVERAGE(Z9:AC9) -> 8.893 | AG9: 2.9 | AH9: 3.9 | AI9: 4.9 | AJ9: 5.9 | AK9: 6.9 | AL9: 7.9 | AM9: 8.9 | AN9: 9.9 | AO9: 10.9 | AP9: 11.9 | AQ9: 12.9 | AR9: 13.9 | AS9: 14.9 | AT9: 15.9 | AU9: 16.9
B10: Pretax Income | F10: =F8-F9 -> 16.385 | G10: =Y10-F10 -> 11.203 | H10: =H8-H9 -> 14.468 | I10: =I8-I9 -> -13.272 | J10: =J8-J9 -> -14.489 | K10: =K8-K9 -> 14.951 | L10: =L8-L9 -> 33.437 | M10: =M8-M9 -> 13.228 | N10: =N8-N9 -> 27.689 | O10: =O8-O9 -> 17.391 | ... R10: =R8-R9 -> 28.334 | S10: =+AE10-R10 -> 15.95 | T10: =T8-T9 -> 27.232 | V10: =V8-V9 -> 2.574 | W10: =W8-W9 -> 21 | X10: =X8-X9 -> 23.934 | Y10: =Y8-Y9 -> 27.588 | Z10: =Z8-Z9 -> 1.196 | AA10: =AA8-AA9 -> 0.462 | AB10: =AB8-AB9 -> 46.665 | AC10: =AC8-AC9 -> 45.08 | ... AU10: =AU8-AU9 -> 81.975772
B11: Taxes | F11: 3.01 | G11: =Y11-F11 -> 2.293 | H11: 2.948 | I11: =Z11-H11 -> -3.137 | J11: -2.856 | K11: =AA11-J11 -> 1.59 | L11: 6.412 | M11: =AB11-L11 -> 2.802 | N11: 5.769 | O11: =AC11-N11 -> 5.16 | P11: 7.581 | Q11: =+AD11-P11 -> 5.267 | R11: 7.701 | S11: =+AE11-R11 -> 1.974 | T11: 7.686 | V11: 1.387 | W11: 2.848 | X11: 5.15 | Y11: 5.303 | Z11: -0.189 | AA11: -1.266 | AB11: 9.214 | AC11: 10.929 | AD11: 12.848 | AE11: 9.675 | AF11: =AF10-AF12 -> 13.348507 | AG11: =AG10*(1-(1-AG19)) -> 11.358393 | AH11: =AH10*(1-(1-AH19)) -> 11.970989 | AI11: =AI10*(1-(1-AI19)) -> 12.537475 | AJ11: =AJ10*(1-(1-AJ19)) -> 13.017448 | AK11: =AK10*(1-(1-AK19)) -> 13.531793 | AL11: =AL10*(1-(1-AL19)) -> 14.082262 | AM11: =AM10*(1-(1-AM19)) -> 14.464212 | AN11: =AN10*(1-(1-AN19)) -> 14.899259 | ... AU11: =AU10*(1-(1-AU19)) -> 16.395154
B12: Net Income | F12: =F10-F11 -> 13.375 | G12: =Y12-F12 -> 8.91 | H12: =H10-H11 -> 11.52 | I12: =I10-I11 -> -10.135 | J12: =J10-J11 -> -11.633 | K12: =K10-K11 -> 13.361 | L12: =L10-L11 -> 27.025 | M12: =M10-M11 -> 10.426 | N12: =N10-N11 -> 21.92 | O12: =O10-O11 -> 12.231 | ... T12: =T10-T11 -> 19.546 | V12: =V10-V11 -> 1.187 | W12: =W10-W11 -> 18.152 | X12: =X10-X11 -> 18.784 | Y12: =Y10-Y11 -> 22.285 | Z12: =Z10-Z11 -> 1.385 | AA12: =AA10-AA11 -> 1.728 | AB12: =AB10-AB11 -> 37.451 | AC12: =AC10-AC11 -> 34.151 | ... AE12: =AE10-AE11 -> 34.609 | AF12: =AF10*(1-AF19) -> 53.394027 | AG12: =AG10-AG11 -> 45.433572 | AH12: =AH10-AH11 -> 47.883957 | AI12: =AI10-AI11 -> 50.149899 | AJ12: =AJ10-AJ11 -> 52.069793 | AK12: =AK10-AK11 -> 54.127172 | AL12: =AL10-AL11 -> 56.329046 | AM12: =AM10-AM11 -> 57.856848 | AN12: =AN10-AN11 -> 59.597037 | ... AU12: =AU10-AU11 -> 65.580617 | AV12: =AU12*(1+$AX$15) -> 64.269005 | AW12: =AV12*(1+$AX$15) -> 62.983625 | AX12: =AW12*(1+$AX$15) -> 61.723953 | AY12: =AX12*(1+$AX$15) -> 60.489473 | AZ12: =AY12*(1+$AX$15) -> 59.279684 | BA12: =AZ12*(1+$AX$15) -> 58.09409 | BB12: =BA12*(1+$AX$15) -> 56.932209 | BC12: =BB12*(1+$AX$15) -> 55.793564 | ... DA12: =CZ12*(1+$AX$15) -> 20.318324
B13: EPS | F13: =F12/F14 -> 0.088853292 | G13: =G12/G14 -> 0.0594 | H13: =H12/H14 -> 0.076442867 | I13: =I12/I14 -> -0.066068394 | J13: =J12/J14 -> -0.073358228 | K13: =K12/K14 -> 0.081168698 | L13: =L12/L14 -> 0.15819934 | M13: =M12/M14 -> 0.060988848 | ... T13: =T12/T14 -> 0.11698822 | V13: =V12/V14 -> 0.011214706 | W13: =W12/W14 -> 0.12101333 | X13: =X12/X14 -> 0.12522667 | Y13: =Y12/Y14 -> 0.14856667 | Z13: =Z12/Z14 -> 0.0090285867 | AA13: =AA12/AA14 -> 0.010497681 | AB13: =AB12/AB14 -> 0.21907667 | AC13: =AC12/AC14 -> 0.19916832 | ... AU13: =AU12/AU14 -> 0.38246556
B14: Shares | F14: 150.52903 | G14: =Y14 -> 150 | H14: 150.70078 | I14: =Z14 -> 153.40164 | J14: 158.57799 | K14: =AA14 -> 164.60779 | L14: 170.82878 | M14: =AB14 -> 170.94929 | N14: 171.22237 | O14: =+AC14 -> 171.46803 | P14: 172.98253 | Q14: =+AD14 -> 171.64789 | R14: 171.93957 | S14: =+AE14 -> 170.62912 | T14: 167.07665 | V14: 105.84317 | W14: 150 | X14: 150 | Y14: 150 | Z14: 153.40164 | AA14: 164.60779 | AB14: 170.94929 | AC14: 171.46803 | AD14: 171.64789 | AE14: 170.62912 | AF14: =+AC14 -> 171.46803 | AG14: =AF14 -> 171.46803 | AH14: =AG14 -> 171.46803 | AI14: =AH14 -> 171.46803 | AJ14: =AI14 -> 171.46803 | AK14: =AJ14 -> 171.46803 | AL14: =AK14 -> 171.46803 | AM14: =AL14 -> 171.46803 | AN14: =AM14 -> 171.46803 | ... AU14: =AT14 -> 171.46803
AW15: Maturity Value | AX15: -0.02
B16: Gross Margin | F16: =F5/F3 -> 0.85857591 | G16: =G5/G3 -> 0.85584383 | H16: =H5/H3 -> 0.85590062 | I16: =I5/I3 -> 0.84701748 | J16: =J5/J3 -> 0.88574715 | K16: =K5/K3 -> 0.85246969 | L16: =L5/L3 -> 0.86382558 | M16: =M5/M3 -> 0.83166253 | ... T16: =T5/T3 -> 0.62765739 | V16: =V5/V3 -> 0.85328664 | W16: =W5/W3 -> 0.86532184 | X16: =X5/X3 -> 0.86106779 | Y16: =Y5/Y3 -> 0.85725284 | Z16: =Z5/Z3 -> 0.8547557 | AA16: =AA5/AA3 -> 0.85729987 | AB16: =AB5/AB3 -> 0.84829231 | AC16: =AC5/AC3 -> 0.63638054 | ... AU16: =AU5/AU3 -> 0.62 | AW16: Discount Rate | AX16: 0.08
B17: Operating Margin | F17: =F8/F3 -> 0.25023138 | G17: =G8/G3 -> 0.18569566 | H17: =H8/H3 -> 0.27698974 | I17: =I8/I3 -> -0.90940154 | J17: =J8/J3 -> -0.96060577 | K17: =K8/K3 -> 0.31901701 | L17: =L8/L3 -> 0.37551037 | M17: =M8/M3 -> 0.19058866 | ... T17: =T8/T3 -> 0.24516211 | V17: =V8/V3 -> 0.13719073 | W17: =W8/W3 -> 0.19480029 | X17: =X8/X3 -> 0.20649036 | Y17: =Y8/Y3 -> 0.21897855 | Z17: =Z8/Z3 -> 0.12407988 | AA17: =AA8/AA3 -> 0.13328139 | AB17: =AB8/AB3 -> 0.28620168 | AC17: =AC8/AC3 -> 0.25146223 | ... AU17: =AU8/AU3 -> 0.23055816 | AW17: NPV | AX17: =NPV(AX16,AG12:DA12) -> 679.46156
B18: Net Margin | F18: =F12/F3 -> 0.19965667 | G18: =G12/G3 -> 0.14164441 | H18: =H12/H3 -> 0.16640185 | I18: =I12/I3 -> -0.98945621 | J18: =J12/J3 -> -1.1150196 | K18: =K12/K3 -> 0.2174465 | L18: =L12/L3 -> 0.26978327 | M18: =M12/M3 -> 0.11142698 | ... T18: =T12/T3 -> 0.13809621 | V18: =V12/V3 -> 0.011326012 | W18: =W12/W3 -> 0.15927278 | X18: =X12/X3 -> 0.15582175 | Y18: =Y12/Y3 -> 0.17156297 | Z18: =Z12/Z3 -> 0.017427302 | AA18: =AA12/AA3 -> 0.024040736 | AB18: =AB12/AB3 -> 0.19330446 | AC18: =AC12/AC3 -> 0.1587813 | ... AU18: =AU12/AU3 -> 0.15292064 | AW18: Net Cash | AX18: =Main!C11 -> 25.994
B19: Tax Rate | F19: =F11/F10 -> 0.18370461 | G19: =G11/G10 -> 0.20467732 | H19: =H11/H10 -> 0.20376002 | I19: =I11/I10 -> 0.23636227 | J19: =J11/J10 -> 0.19711505 | K19: =K11/K10 -> 0.1063474 | L19: =L11/L10 -> 0.19176362 | M19: =M11/M10 -> 0.2118234 | ... T19: =T11/T10 -> 0.28224148 | V19: =V11/V10 -> 0.53885004 | W19: =W11/W10 -> 0.13561905 | X19: =X11/X10 -> 0.21517506 | Y19: =Y11/Y10 -> 0.19222126 | Z19: =Z11/Z10 -> -0.15802676 | AA19: =AA11/AA10 -> -2.7402597 | AB19: =AB11/AB10 -> 0.19744991 | AC19: =AC11/AC10 -> 0.24243567 | ... AE19: =AE11/AE10 -> 0.2184762 | AF19: 0.2 | AG19: =AF19 -> 0.2 | AH19: =AG19 -> 0.2 | AI19: =AH19 -> 0.2 | AJ19: =AI19 -> 0.2 | AK19: =AJ19 -> 0.2 | AL19: =AK19 -> 0.2 | AM19: =AL19 -> 0.2 | AN19: =AM19 -> 0.2 | ... AU19: =AT19 -> 0.2 | AW19: Total Value | AX19: =AX17+AX18 -> 705.45556
AW20: Per Share | AX20: =AX19/Main!C7 -> 4.2223468
B21: Revenue Y/Y | F21: - | G21: - | H21: =H3/F3-1 -> 0.033437827 | I21: =I3/G3-1 -> -0.83716457 | J21: =J3/H3-1 -> -0.84929944 | K21: =K3/I3-1 -> 4.9987308 | L21: =L3/J3-1 -> 8.6015528 | M21: =M3/K3-1 -> 0.52279274 | N21: =N3/L3-1 -> 0.098619388 | O21: =O3/M3-1 -> 0.12249915 | ... T21: =T3/R3-1 -> 0.095087776 | V21: - | W21: =W3/V3-1 -> 0.087449787 | X21: =X3/W3-1 -> 0.057735505 | Y21: =Y3/X3-1 -> 0.077529283 | Z21: =Z3/Y3-1 -> -0.38817035 | AA21: =AA3/Z3-1 -> -0.095567048 | AB21: =AB3/AA3-1 -> 1.6954145 | AC21: =AC3/AB3-1 -> 0.11015221 | AD21: =AD3/AC3-1 -> 0.0712147 | AE21: =AE3/AD3-1 -> 0.08794743 | AF21: 0.11 | AG21: 0.08 | AH21: 0.07 | AI21: 0.06 | AJ21: 0.05 | AK21: 0.05 | AL21: 0.05 | AM21: 0.04 | AN21: 0.04 | AO21: 0.04 | AP21: 0.02 | AQ21: 0.02 | AR21: 0.02 | AS21: 0.02 | AT21: 0.02 | AU21: 0.02 | AW21: Current Share Price | AX21: =Main!C6 -> 3.04
B22: Revenue H/H | F22: - | G22: =G3/F3-1 -> -0.060994178 | H22: =H3/G3-1 -> 0.10056594 | I22: =I3/H3-1 -> -0.85204391 | J22: =J3/I3-1 -> 0.018549253 | K22: =K3/J3-1 -> 4.8894853 | L22: =L3/K3-1 -> 0.63028725 | M22: =M3/L3-1 -> -0.065935931 | N22: =N3/M3-1 -> 0.17617134 | ... T22: =T3/S3-1 -> 0.16576479 | V22: - | W22: - | X22: - | Y22: - | Z22: - | AA22: - | AB22: - | AC22: - | AD22: - | AE22: - | AG22: - | AH22: - | AI22: - | AJ22: - | AK22: - | AL22: - | AM22: - | AN22: - | AO22: - | AP22: - | AQ22: - | AR22: - | AS22: - | AT22: - | AU22: - | AW22: Projected Upside | AX22: =AX20/AX21-1 -> 0.38892985
AW23: Market Cap | AX23: =+AX20*Main!C7 -> 705.45556
B24: Non-Finance Metrics
B25: No. Sites | N25: 69 | O25: =+AC25 -> 71 | P25: 71 | R25: 75 | V25: 54 | W25: 58 | Y25: =SUM(Y26:Y29) -> 60 | AA25: =SUM(AA26:AA29) -> 64 | AB25: =SUM(AB26:AB29) -> 67 | AC25: =SUM(AC26:AC29) -> 71 | AD25: =72+13 -> 85 | AE25: 92
B26: Hollywood Bowl | O26: =+AC26 -> 62 | Y26: 54 | AA26: 56 | AB26: 59 | AC26: 62 | AE26: 77
B27: AMF Bowling | O27: =+AC27 -> 3 | Y27: 6 | AA27: 5 | AB27: 3 | AC27: 3 | AE27: 15
B28: Splitsville (CA)
B29: Puttstars | O29: =+AC29 -> 6 | Y29: 0 | AA29: 3 | AB29: 5 | AC29: 6
B30: Rev Per Site | V30: =V3/V25 -> 1.9407963 | W30: =W3/W25 -> 1.9649655 | Y30: =Y3/Y25 -> 2.1649 | AA30: =AA3/AA25 -> 1.1230938 | AB30: =AB3/AB25 -> 2.8916567 | AC30: =AC3/AC25 -> 3.0293239 | AD30: =AD3/AD25 -> 2.7105765 | AE30: =AE3/AE25 -> 2.724587
B31: Games Played | V31: 12.1 | W31: 13.1
B32: Rev per Game Played | V32: =V3/V31 -> 8.661405 | W32: =W3/W31 -> 8.6998473
AH33: o
B34: Staff | V34: =SUM(V35:V37) -> 0 | W34: =SUM(W35:W37) -> 0 | X34: =SUM(X35:X37) -> 0 | Y34: =SUM(Y35:Y37) -> 0 | Z34: =SUM(Z35:Z37) -> 0 | AA34: =SUM(AA35:AA37) -> 1787 | AB34: =SUM(AB35:AB37) -> 2530 | AC34: =SUM(AC35:AC37) -> 2787 | ... AE34: =SUM(AE35:AE37) -> 2882
B35: Directors | AA35: 6 | AB35: 7 | AC35: 7 | AD35: 7 | AE35: 9
B36: Administration | AA36: 58 | AB36: 91 | AC36: 112 | AD36: 118 | AE36: 130
B37: Operations | AA37: 1723 | AB37: 2432 | AC37: 2668 | AD37: 2701 | AE37: 2743
B38: Y/Y | AB38: =+AB34/AA34-1 -> 0.41578064 | AC38: =+AC34/AB34-1 -> 0.10158103 | AD38: =+AD34/AC34-1 -> 0.013993541 | AE38: =+AE34/AD34-1 -> 0.019815994
B40: Balance Sheet
B41: PP&E | H41: 48.181 | L41: 55.977 | N41: 74.734 | P41: 91.209 | R41: 114.261 | T41: 121.367 | AA41: 49.036 | AB41: 68.641 | AC41: 78.279 | AD41: 101.936 | AE41: 121.737
...

Sheet Historical Projections
A1: H222 | B1: H222 | Q1: FY22 | R1: FY22
A2: 44834 | B2: (Projected) | Q2: 44834 | R2: (Projected)
A3: 93.568 | B3: 158.5878 | Q3: 193.741 | R3: 258.7608
A4: 15.751 | B4: 22.585512 | Q4: 29.392 | R4: 36.226512
A5: 77.817 | B5: 136.00229 | Q5: 164.349 | R5: 222.53429
A6: 0.039 | B6: 0.4 | Q6: 0.039 | R6: 0.4
A7: 60.023 | B7: 84.604573 | Q7: 108.939 | R7: 133.52057
A8: 17.833 | B8: 51.797715 | Q8: 55.449 | R8: 89.413715
A9: 4.605 | B9: -1.079 | Q9: 8.784 | R9: 3.1
A10: 13.228 | B10: 52.876715 | Q10: 46.665 | R10: 86.313715
A11: 2.802 | B11: 3.938432 | Q11: 9.214 | R11: 10.350432
A12: 10.426 | B12: 48.938283 | Q12: 37.451 | R12: 75.963283
A13: 0.060988848 | B13: 0.29730235 | Q13: 0.21907667 | R13: 0.46148048
A14: 170.94929 | B14: 164.60779 | Q14: 170.94929 | R14: 164.60779
... A21: 0.52279274 | B21: 1.5809716 | Q21: 1.6954145 | R21: 2.6
A22: -0.065935931 | B22: 0.58313917 | Q22: - | R22: -
